<?xml version="1.0"?>
<robot name="mira">

    <material name="red">
        <color rgba="0.8 0 0 1"/>
    </material>
    <material name="orange">
        <color rgba="1 0.6 0 1"/>
    </material>
    <material name="blue">
        <color rgba="0 0 1 0.5"/>
    </material>
    <material name="gray">
        <color rgba="0.75 0.75 0.75 0.5"/>
    </material>
    <material name="yellow">
        <color rgba="1 1 0 0.5"/>
    </material>
    <material name="white">
        <color rgba="1 1 1 1"/>
    </material>

    <link name="base_link">
         <inertial>
            <origin xyz="0 0 0" rpy="0 0 0"/>
            <mass value="0.18" />
            <inertia ixx="0.0002835" ixy="0.0" ixz="0.0" iyy="0.0002835" iyz="0.0" izz="0.000324"/>
        </inertial>

        <collision>
            <origin xyz="0 0 0" rpy="0 0 0"/>
            <geometry>
                <cylinder radius="0.06" length="0.09"/>
            </geometry>
        </collision>

        <visual>
        <origin rpy="0 0 0" xyz="0 0 0"/>
        <geometry>
            <cylinder radius="0.06" length="0.09"/>
        </geometry>
        <material name="gray"/>
        </visual>
    </link>

    <gazebo reference="base_link">
        <kp>100000.0</kp>
        <kd>100000.0</kd>
        <mu1>10.0</mu1>
        <mu2>10.0</mu2>
        <material>Gazebo/Grey</material>
    </gazebo>

    <link name="roll_M1_link">
        <inertial>
            <origin xyz="0 0 0" rpy="0 0 0"/>
            <mass value="0.001" />
            <inertia ixx="2.70833333333e-08" ixy="0.0" ixz="0.0" iyy="2.70833333333e-08" iyz="0.0" izz="5e-08"/>
        </inertial>

        <visual>
        <origin rpy="0 0 0" xyz="0 0 0"/>
        <geometry>
            <cylinder length="0.005" radius="0.01"/>
        </geometry>
        <material name="green"/>
        </visual>
    </link>

    <gazebo reference="roll_M1_link">
        <kp>100000.0</kp>
        <kd>100000.0</kd>
        <mu1>10.0</mu1>
        <mu2>10.0</mu2>
        <material>Gazebo/Red</material>
    </gazebo>

    <link name="pitch_M2_link">
        <inertial>
            <origin xyz="0 0 0" rpy="0 0 0"/>
            <mass value="0.001" />
            <inertia ixx="2.70833333333e-08" ixy="0.0" ixz="0.0" iyy="2.70833333333e-08" iyz="0.0" izz="5e-08"/>
        </inertial>
        <visual>
        <origin rpy="0 0 0" xyz="0 0 0"/>
        <geometry>
            <cylinder length="0.005" radius="0.01"/>
        </geometry>
        <material name="blue"/>
        </visual>
    </link>

    <gazebo reference="pitch_M3_link">
        <kp>100000.0</kp>
        <kd>100000.0</kd>
        <mu1>10.0</mu1>
        <mu2>10.0</mu2>
        <material>Gazebo/Green</material>
    </gazebo>

    <link name="yaw_M3_link">
        <inertial>
            <origin xyz="0 0 0" rpy="0 0 0"/>
            <mass value="0.001" />
            <inertia ixx="2.70833333333e-08" ixy="0.0" ixz="0.0" iyy="2.70833333333e-08" iyz="0.0" izz="5e-08"/>
        </inertial>
        <visual>
        <origin rpy="0 0 0" xyz="0 0 0"/>
        <geometry>
            <cylinder length="0.005" radius="0.01"/>
        </geometry>
        <material name="yellow"/>
        </visual>
    </link>

    <gazebo reference="yaw_M3_link">
        <kp>100000.0</kp>
        <kd>100000.0</kd>
        <mu1>10.0</mu1>
        <mu2>10.0</mu2>
        <material>Gazebo/Yellow</material>
    </gazebo>

    <link name="head_link">
        <inertial>
            <origin xyz="0 0 0" rpy="0 0 0"/>
            <mass value="0.001" />
            <inertia ixx="2.88e-05" ixy="0.0" ixz="0.0" iyy="2.88e-05" iyz="0.0" izz="2.88e-05"/>
        </inertial>

        <collision>
            <origin xyz="0 0 0.015" rpy="0 0 0"/>
            <geometry>
                <sphere radius="0.06"/>
            </geometry>
        </collision>

        <visual>
        <origin rpy="0 0 0" xyz="0 0 0"/>
        <geometry>
            <sphere radius="0.06"/>
        </geometry>
        <material name="gray"/>
        </visual>
    </link>

    <gazebo reference="head_link">
        <kp>100000.0</kp>
        <kd>100000.0</kd>
        <mu1>10.0</mu1>
        <mu2>10.0</mu2>
        <material>Gazebo/Grey</material>
    </gazebo>

    <link name="left_eye_link">
        <inertial>
            <origin xyz="0 0 0" rpy="0 0 0"/>
            <mass value="0.001" />
            <inertia ixx="9.1875e-09" ixy="0.0" ixz="0.0" iyy="9.1875e-09" iyz="0.0" izz="1.378125e-08"/>
        </inertial>
        <visual>
        <origin rpy="0 0 0" xyz="0 0 0"/>
        <geometry>
            <cylinder radius="0.00525" length="0.00525"/>
        </geometry>
        </visual>
    </link>

    <gazebo reference="left_eye_link">
        <kp>100000.0</kp>
        <kd>100000.0</kd>
        <mu1>10.0</mu1>
        <mu2>10.0</mu2>
        <material>Gazebo/Red</material>
    </gazebo>

    <link name="right_eye_link">
        <inertial>
            <origin xyz="0 0 0" rpy="0 0 0"/>
            <mass value="0.001" />
            <inertia ixx="2.70833333333e-08" ixy="0.0" ixz="0.0" iyy="2.70833333333e-08" iyz="0.0" izz="5e-08"/>
        </inertial>
        <visual>
        <origin rpy="0 0 0" xyz="0 0 0"/>
        <geometry>
            <cylinder radius="0.00525" length="0.00525"/>
        </geometry>
        </visual>
    </link>

    <gazebo reference="right_eye_link">
        <kp>100000.0</kp>
        <kd>100000.0</kd>
        <mu1>10.0</mu1>
        <mu2>10.0</mu2>
        <material>Gazebo/Red</material>
    </gazebo>

    <link name="camera_link">
        <inertial>
            <origin xyz="0 0 0" rpy="0 0 0"/>
            <mass value="0.001" />
            <inertia ixx="4.16666666667e-11" ixy="0.0" ixz="0.0" iyy="4.16666666667e-11" iyz="0.0" izz="4.16666666667e-11"/>
        </inertial>
        <visual>
        <origin rpy="0 0 0" xyz="0 0 0"/>
        <geometry>
            <box size="0.0005 0.0005 0.0005"/>
        </geometry>
        </visual>
    </link>

    <gazebo reference="camera_link">
        <kp>100000.0</kp>
        <kd>100000.0</kd>
        <mu1>10.0</mu1>
        <mu2>10.0</mu2>
        <material>Gazebo/Red</material>
    </gazebo>

    <joint name="roll_joint" type="revolute">
        <parent link="base_link"/>
        <child link="roll_M1_link"/>
        <origin xyz="0 0 0.04" rpy="0 -1.55 0"/>
        <limit lower="-0.2" upper="0.2" effort="0.1" velocity="0.005"/>
        <axis xyz="1 0 0"/>
    </joint>

    <joint name="pitch_joint" type="revolute">
        <parent link="roll_M1_link"/>
        <child link="pitch_M2_link"/>
        <origin xyz="0 0 0" rpy="0 1.58 0"/>
        <limit lower="-0.2" upper="0.2" effort="0.1" velocity="0.005"/>
        <axis xyz="0 1 0"/>
    </joint>

    <joint name="yaw_joint" type="continuous">
        <parent link="pitch_M2_link"/>
        <child link="yaw_M3_link"/>
        <origin xyz="0 0 0.01" rpy="0 0 0"/>
        <limit lower="0" upper="0" effort="0.1" velocity="0.01"/>
        <axis xyz="0 0 1"/>
    </joint>

    <joint name="base_head_joint" type="fixed">
        <parent link="yaw_M3_link"/>
        <child link="head_link"/>
        <origin xyz=" 0 0 0.005" rpy="0 0 0"/>
    </joint>

    <joint name="head_lefteye_joint" type="fixed">
        <parent link="head_link"/>
        <child link="left_eye_link"/>
        <origin xyz="0.025 0.05295 0.005" rpy="-1.5 0 -0.24"/>
    </joint>

    <joint name="head_righteye_joint" type="fixed">
        <parent link="head_link"/>
        <child link="right_eye_link"/>
        <origin xyz=" -0.028 0.05295 0.005" rpy="-1.5 0 0.38"/>
    </joint>

    <joint name="head_camera_joint" type="fixed">
        <parent link="head_link"/>
        <child link="camera_link"/>
        <origin xyz="0.0007 0.056 0.02" rpy="0 0 0"/>
    </joint>
</robot>