<?xml version="1.0"?>
<robot name="gurdy">

    <material name="red">
        <color rgba="0.8 0 0 1"/>
    </material>
    <material name="orange">
        <color rgba="1 0.6 0 1"/>
    </material>
    <material name="blue">
        <color rgba="0 0 1 0.5"/>
    </material>
    <material name="gray">
        <color rgba="0.75 0.75 0.75 0.5"/>
    </material>
    <material name="yellow">
        <color rgba="1 1 0 0.5"/>
    </material>
    <material name="purple">
        <color rgba="0.6 0.6 0 0.8"/>
    </material>

    <link name="base_link">
        <visual>
        <origin rpy="0 0 0" xyz="0 0 0"/>
        <geometry>
            <box size="0.01 0.01 0.01"/>
        </geometry>
        <material name="gray"/>
        </visual>     
    </link>

    <gazebo>
        <plugin name="gazebo_ros_imu_controller" filename="libgazebo_ros_imu.so">
            <robotNamespace>/gurdy</robotNamespace>
            <topicName>imu/data</topicName>
      `     <serviceName>imu/service</serviceName>
            <bodyName>base_link</bodyName>
            <gaussianNoise>0</gaussianNoise>
            <rpyOffsets>0 0 0</rpyOffsets>
            <updateRate>10.0</updateRate>
            <alwaysOn>true</alwaysOn>
            <gaussianNoise>0</gaussianNoise>
        </plugin>
    </gazebo> 

    <gazebo reference="base_link">
        <kp>1000.0</kp>
        <kd>1000.0</kd>
        <mu1>10.0</mu1>
        <mu2>10.0</mu2>
        <material>Gazebo/Black</material>
    </gazebo>

    <link name="head_link">
         <inertial>
            <origin xyz="0 0 0" rpy="0 0 0"/>
            <mass value="0.01" />
            <inertia ixx="7.58333333333e-06" ixy="0.0" ixz="0.0" iyy="7.58333333333e-06" iyz="0.0" izz="1.25e-05"/>
        </inertial>

        <collision>
            <origin xyz="0 0 0" rpy="0 0 0"/>
            <geometry>
                <cylinder radius="0.05" length="0.04"/>
            </geometry>
        </collision>

        <visual>
        <origin rpy="0 0 0" xyz="0 0 0"/>
        <geometry>
            <mesh filename="package://my_gurdy_description/models/gurdy/meshes/gurdy_head_v2.dae"/>
        </geometry>
        <material name="gray"/>
        </visual>
    </link>
    
    <gazebo>
        <plugin name="gazebo_ros_control" filename="libgazebo_ros_control.so">
            <robotNamespace>/gurdy</robotNamespace>
        </plugin>
    </gazebo>

    <joint name="base_head_joint" type="fixed">
        <parent link="base_link"/>
        <child link="head_link"/>
        <origin xyz="0 0 0" rpy="0 -0 0"/>
    </joint>

    <link name="upper_leg_M1_link">
         <inertial>
            <origin xyz="0 0 0" rpy="0 0 0"/>
            <mass value="0.01" />
            <inertia ixx="7.58333333333e-06" ixy="0.0" ixz="0.0" iyy="7.58333333333e-06" iyz="0.0" izz="1.25e-05"/>
        </inertial>

        <collision>
            <origin xyz="0 0 0" rpy="0 0 0"/>
            <geometry>
                <cylinder radius="0.0025" length="0.06"/>
            </geometry>
        </collision>

        <visual>
        <origin rpy="0 0 0" xyz="0 0 0"/>
        <geometry>
            <mesh filename="package://my_gurdy_description/models/gurdy/meshes/gurdy_higherleg_v2.dae"/>
        </geometry>
        <material name="red"/>
        </visual>
    </link>

    <gazebo reference="upper_leg_M1_link">
        <kp>1000.0</kp>
        <kd>1000.0</kd>
        <mu1>10.0</mu1>
        <mu2>10.0</mu2>
        <material>Gazebo/Red</material>
    </gazebo>
    
    <joint name="head_upperlegM1_joint" type="revolute">
        <parent link="head_link"/>
        <child link="upper_leg_M1_link"/>
        <origin xyz="-0.02165 -0.0125 -0.008" rpy="3.14159 -1.05879e-22 0.523599"/>
        <limit lower="-2" upper="0" effort="1" velocity="0.005"/>
        <axis xyz="0 1 0"/>
    </joint>

    <transmission name="tran1">
        <type>transmission_interface/SimpleTransmission</type>
        <joint name="head_upperlegM1_joint">
            <hardwareInterface>EffortJointInterface</hardwareInterface>
        </joint>
        <actuator name="motor1">
            <hardwareInterface>EffortJointInterface</hardwareInterface>
            <mechanicalReduction>1</mechanicalReduction>
        </actuator>
    </transmission>

    <link name="upper_leg_M2_link">
         <inertial>
            <origin xyz="0 0 0" rpy="0 0 0"/>
            <mass value="0.01" />
            <inertia ixx="7.58333333333e-06" ixy="0.0" ixz="0.0" iyy="7.58333333333e-06" iyz="0.0" izz="1.25e-05"/>
        </inertial>

        <collision>
            <origin xyz="0 0 0" rpy="0 0 0"/>
            <geometry>
                <cylinder radius="0.0025" length="0.06"/>
            </geometry>
        </collision>

        <visual>
        <origin rpy="0 0 0" xyz="0 0 0"/>
        <geometry>
            <mesh filename="package://my_gurdy_description/models/gurdy/meshes/gurdy_higherleg_v2.dae"/>
        </geometry>
        <material name="yellow"/>
        </visual>
    </link>

    <gazebo reference="upper_leg_M2_link">
        <kp>1000.0</kp>
        <kd>1000.0</kd>
        <mu1>10.0</mu1>
        <mu2>10.0</mu2>
        <material>Gazebo/Black</material>
    </gazebo>

    <joint name="head_upperlegM2_joint" type="revolute">
        <parent link="head_link"/>
        <child link="upper_leg_M2_link"/>
        <origin xyz="0.02165 -0.0125 -0.008" rpy="3.14159 -0 2.61799"/>
        <limit lower="-2" upper="0" effort="1" velocity="0.005"/>
        <axis xyz="0 1 0"/>
    </joint>

    <transmission name="tran2">
        <type>transmission_interface/SimpleTransmission</type>
        <joint name="head_upperlegM2_joint">
            <hardwareInterface>EffortJointInterface</hardwareInterface>
        </joint>
        <actuator name="motor2">
            <hardwareInterface>EffortJointInterface</hardwareInterface>
            <mechanicalReduction>1</mechanicalReduction>
        </actuator>
    </transmission>

    <link name="upper_leg_M3_link">
        <inertial>
            <origin xyz="0 0 0" rpy="0 0 0"/>
            <mass value="0.01" />
            <inertia ixx="7.58333333333e-06" ixy="0.0" ixz="0.0" iyy="7.58333333333e-06" iyz="0.0" izz="1.25e-05"/>
        </inertial>

        <collision>
            <origin xyz="0 0 0" rpy="0 0 0"/>
            <geometry>
                <cylinder radius="0.0025" length="0.06"/>
            </geometry>
        </collision>

        <visual>
        <origin rpy="0 0 0" xyz="0 0 0"/>
        <geometry>
            <mesh filename="package://my_gurdy_description/models/gurdy/meshes/gurdy_higherleg_v2.dae"/>
        </geometry>
        <material name="orange"/>
        </visual>
    </link>

    <gazebo reference="upper_leg_M3_link">
        <kp>1000.0</kp>
        <kd>1000.0</kd>
        <mu1>10.0</mu1>
        <mu2>10.0</mu2>
        <material>Gazebo/Blue</material>
    </gazebo>

    <joint name="head_upperlegM3_joint" type="revolute">
        <parent link="head_link"/>
        <child link="upper_leg_M3_link"/>
        <origin xyz="0 0.025 -0.008" rpy="3.14159 -0 -1.5708"/>
        <limit lower="-2" upper="0" effort="1" velocity="0.005"/>
        <axis xyz="0 1 0"/>
    </joint>

    <transmission name="tran3">
        <type>transmission_interface/SimpleTransmission</type>
        <joint name="head_upperlegM3_joint">
            <hardwareInterface>EffortJointInterface</hardwareInterface>
        </joint>
        <actuator name="motor3">
            <hardwareInterface>EffortJointInterface</hardwareInterface>
            <mechanicalReduction>1</mechanicalReduction>
        </actuator>
    </transmission>

    <link name="lowerleg_M1_link">
        <inertial>
            <origin xyz="0 0 0" rpy="0 0 0"/>
            <mass value="0.01" />
            <inertia ixx="9.001875e-06" ixy="0.0" ixz="0.0" iyy="9.001875e-06" iyz="0.0" izz="1.8e-05"/>
        </inertial>

        <collision>
            <origin xyz="0 0 0" rpy="0 0 0"/>
            <geometry>
                <cylinder radius="0.0015" length="0.06"/>
            </geometry>
        </collision>

        <visual>
        <origin rpy="0 0 0" xyz="0 0 0"/>
        <geometry>
            <mesh filename="package://my_gurdy_description/models/gurdy/meshes/gurdy_lowerleg_v2.dae"/>
        </geometry>
        <material name="gray"/>
        </visual>
    </link>

    <gazebo reference="lowerleg_M1_link">
        <kp>1000.0</kp>
        <kd>1000.0</kd>
        <mu1>10.0</mu1>
        <mu2>10.0</mu2>
        <material>Gazebo/Green</material>
    </gazebo>

    <joint name="upperlegM1_lowerlegM1_joint" type="continuous">
        <parent link="upper_leg_M1_link"/>
        <child link="lowerleg_M1_link"/>
        <origin xyz="0 0.0095 0.06" rpy="0 -0 3.14159"/>
        <limit lower="-2.9" upper="1.5708" effort="1.0" velocity="0.005"/>
        <axis xyz="0 1 0"/>
    </joint>

    <transmission name="tran4">
        <type>transmission_interface/SimpleTransmission</type>
        <joint name="upperlegM1_lowerlegM1_joint">
            <hardwareInterface>EffortJointInterface</hardwareInterface>
        </joint>
        <actuator name="motor4">
            <hardwareInterface>EffortJointInterface</hardwareInterface>
            <mechanicalReduction>1</mechanicalReduction>
        </actuator>
    </transmission>

    <link name="lowerleg_M2_link">
        <inertial>
            <origin xyz="0 0 0" rpy="0 0 0"/>
            <mass value="0.01" />
            <inertia ixx="9.001875e-06" ixy="0.0" ixz="0.0" iyy="9.001875e-06" iyz="0.0" izz="1.8e-05"/>
        </inertial>

        <collision>
            <origin xyz="0 0 0" rpy="0 0 0"/>
            <geometry>
                <cylinder radius="0.0015" length="0.06"/>
            </geometry>
        </collision>

        <visual>
        <origin rpy="0 0 0" xyz="0 0 0"/>
        <geometry>
            <mesh filename="package://my_gurdy_description/models/gurdy/meshes/gurdy_lowerleg_v2.dae"/>
        </geometry>
        <material name="red"/>
        </visual>
    </link>

    <gazebo reference="lowerleg_M2_link">
        <kp>1000.0</kp>
        <kd>1000.0</kd>
        <mu1>10.0</mu1>
        <mu2>10.0</mu2>
        <material>Gazebo/Green</material>
    </gazebo>

    <joint name="upperlegM2_lowerlegM2_joint" type="revolute">
        <parent link="upper_leg_M2_link"/>
        <child link="lowerleg_M2_link"/>
        <origin xyz="0 0.0095 0.06" rpy="0 -0 3.14159"/>
        <limit lower="-2.9" upper="1.5708" effort="1.0" velocity="0.005"/>
        <axis xyz="0 1 0"/>
    </joint>
    
    <transmission name="tran5">
        <type>transmission_interface/SimpleTransmission</type>
        <joint name="upperlegM2_lowerlegM2_joint">
            <hardwareInterface>EffortJointInterface</hardwareInterface>
        </joint>
        <actuator name="motor5">
            <hardwareInterface>EffortJointInterface</hardwareInterface>
            <mechanicalReduction>1</mechanicalReduction>
        </actuator>
    </transmission>

    <link name="lowerleg_M3_link">
        <inertial>
            <origin xyz="0 0 0" rpy="0 0 0"/>
            <mass value="0.01" />
            <inertia ixx="9.001875e-06" ixy="0.0" ixz="0.0" iyy="9.001875e-06" iyz="0.0" izz="1.8e-05"/>
        </inertial>

        <collision>
            <origin xyz="0 0 0" rpy="0 0 0"/>
            <geometry>
                <cylinder radius="0.0015" length="0.06"/>
            </geometry>
        </collision>

        <visual>
        <origin rpy="0 0 0" xyz="0 0 0"/>
        <geometry>
            <mesh filename="package://my_gurdy_description/models/gurdy/meshes/gurdy_higherleg_v2.dae"/>
        </geometry>
        <material name="orange"/>
        </visual>
    </link>

    <gazebo reference="lowerleg_M3_link">
        <kp>1000.0</kp>
        <kd>1000.0</kd>
        <mu1>10.0</mu1>
        <mu2>10.0</mu2>
        <material>Gazebo/Orange</material>
    </gazebo>

    <joint name="upperlegM3_lowerlegM3_joint" type="continuous">
        <parent link="upper_leg_M3_link"/>
        <child link="lowerleg_M3_link"/>
        <origin xyz="0 0.0095 0.06" rpy="0 -0 3.14159"/>
        <limit lower="-2.9" upper="1.5708" effort="1.0" velocity="0.005"/>
        <axis xyz="0 1 0"/>
    </joint>

    <transmission name="tran6">
        <type>transmission_interface/SimpleTransmission</type>
        <joint name="upperlegM3_lowerlegM3_joint">
            <hardwareInterface>EffortJointInterface</hardwareInterface>
        </joint>
        <actuator name="motor6">
            <hardwareInterface>EffortJointInterface</hardwareInterface>
            <mechanicalReduction>1</mechanicalReduction>
        </actuator>
    </transmission>

    <link name="foot_M1_link">
        <inertial>
            <origin xyz="0 0 0" rpy="0 0 0"/>
            <mass value="0.01" />
            <inertia ixx="2.56e-07" ixy="0.0" ixz="0.0" iyy="2.56e-07" iyz="0.0" izz="2.56e-07"/>
        </inertial>

        <collision>
            <origin xyz="0 0 0" rpy="0 0 0"/>
            <geometry>
                <sphere radius="0.008"/>
            </geometry>
        </collision>

        <visual>
        <origin rpy="0 0 0" xyz="0 0 0"/>
        <geometry>
            <sphere radius="0.008"/>
        </geometry>
        <material name="orange"/>
        </visual>
    </link>

    <gazebo reference="foot_M1_link">
        <kp>1000.0</kp>
        <kd>1000.0</kd>
        <mu1>10.0</mu1>
        <mu2>10.0</mu2>
        <material>Gazebo/Red</material>
    </gazebo>

    <joint name="basefoot_peg_M1_lowerleg_M1_joint" type="fixed">
        <parent link="lowerleg_M1_link"/>
        <child link="foot_M1_link"/>
        <origin xyz="0 0 0.06" rpy="0 -0 0"/>
    </joint>

    <link name="foot_M2_link">
        <inertial>
            <origin xyz="0 0 0" rpy="0 0 0"/>
            <mass value="0.01" />
            <inertia ixx="2.56e-07" ixy="0.0" ixz="0.0" iyy="2.56e-07" iyz="0.0" izz="2.56e-07"/>
        </inertial>

        <collision>
            <origin xyz="0 0 0" rpy="0 0 0"/>
            <geometry>
                <sphere radius="0.008"/>
            </geometry>
        </collision>

        <visual>
        <origin rpy="0 0 0" xyz="0 0 0"/>
        <geometry>
            <sphere radius="0.008"/>
        </geometry>
        <material name="orange"/>
        </visual>
    </link> 

    <gazebo reference="foot_M2_link">
        <kp>1000.0</kp>
        <kd>1000.0</kd>
        <mu1>10.0</mu1>
        <mu2>10.0</mu2>
        <material>Gazebo/Green</material>
    </gazebo>

    <joint name="basefoot_peg_M2_lowerleg_M2_joint" type="fixed">
        <parent link="lowerleg_M2_link"/>
        <child link="foot_M2_link"/>
        <origin xyz="0 0 0.06" rpy="0 -0 0"/>
    </joint>
    
    <link name="foot_M3_link">
        <inertial>
            <origin xyz="0 0 0" rpy="0 0 0"/>
            <mass value="0.01" />
            <inertia ixx="2.56e-07" ixy="0.0" ixz="0.0" iyy="2.56e-07" iyz="0.0" izz="2.56e-07"/>
        </inertial>

        <collision>
            <origin xyz="0 0 0" rpy="0 0 0"/>
            <geometry>
                <sphere radius="0.008"/>
            </geometry>
        </collision>

        <visual>
        <origin rpy="0 0 0" xyz="0 0 0"/>
        <geometry>
            <sphere radius="0.008"/>
        </geometry>
        <material name="orange"/>
        </visual>
    </link> 

    <gazebo reference="foot_M3_link">
        <kp>1000.0</kp>
        <kd>1000.0</kd>
        <mu1>10.0</mu1>
        <mu2>10.0</mu2>
        <material>Gazebo/Green</material>
    </gazebo>

    <joint name="basefoot_peg_M3_lowerleg_M3_joint" type="fixed">
        <parent link="lowerleg_M3_link"/>
        <child link="foot_M3_link"/>
        <origin xyz="0 0 0.06" rpy="0 -0 0"/>
    </joint>
</robot>
   