<?xml version="1.0"?>
<robot name="jibo">

    <link name="dummy"></link>  
    <joint name="dummy_joint" type="fixed">
        <parent link="dummy"/>
        <child link="base_link"/>
    </joint>

    <link name="base_link">
        <inertial>
            <origin xyz="0 0 0" rpy="0 0 0"/>
            <mass value="1.0" />
            <inertia ixx="0.00091875" ixy="0.0" ixz="0.0" iyy="0.00091875" iyz="0.0" izz="0.0018"/>
        </inertial>
        <collision>
            <origin xyz="0 0 0" rpy="0 0 0"/>
            <geometry>
                <cylinder radius="0.06" length="0.015"/>
            </geometry>
        </collision>
        <visual>
            <origin rpy="0.0 0 0" xyz="0 0 0"/>
            <geometry>
                <mesh filename="package://jibo_description/models/jibo/meshes/jibo_final_parts_base_v3.dae"/>
            </geometry>
        </visual>
    </link>

    <gazebo reference="base_link">
        <kp>100.0</kp>
        <kd>100.0</kd>
        <mu1>10.0</mu1>
        <mu2>10.0</mu2>
        <material>Gazebo/Black</material>
    </gazebo>

    <gazebo>
        <plugin name="gazebo_ros_control" filename="libgazebo_ros_control.so">
        </plugin>
    </gazebo>

    <link name="waist_link">
            <inertial>
            <origin xyz="0 0 0" rpy="0 0 0"/>
            <mass value="0.2" />
            <inertia ixx="0.000286666666667" ixy="0.0" ixz="0.0" iyy="0.000286666666667" iyz="0.0" izz="0.00049"/>
        </inertial>
        <collision>
            <origin xyz="0 0 0.03" rpy="0 0 0"/>
            <geometry>
                <cylinder radius="0.07" length="0.05"/>
            </geometry>
        </collision>
                <visual>
            <origin rpy="0.0 0 0" xyz="0 0 0"/>
            <geometry>
                <mesh filename="package://jibo_description/models/jibo/meshes/jibo_final_parts_waist_v3.dae"/>
            </geometry>
        </visual>
        </link>
    <gazebo reference="waist_link">
        <kp>100.0</kp>
        <kd>100.0</kd>
        <mu1>10.0</mu1>
        <mu2>10.0</mu2>
        <material>Gazebo/Blue</material>
    </gazebo>

    
    <joint name="base_waist_joint" type="continuous">
        <parent link="base_link"/>
        <child link="waist_link"/>
        <origin xyz="0 0 0" rpy="0 0 0"/>
        <limit effort="1.0" velocity="1.0"/>
        <axis xyz="0 0 1"/>
        </joint>

    <transmission name="tran1">
        <type>transmission_interface/SimpleTransmission</type>
        <joint name="base_waist_joint">
            <hardwareInterface>EffortJointInterface</hardwareInterface>
        </joint>
        <actuator name="motor1">
            <hardwareInterface>EffortJointInterface</hardwareInterface>
            <mechanicalReduction>1</mechanicalReduction>
        </actuator>
    </transmission>


    <link name="body_link">
            <inertial>
            <origin xyz="0 0 0" rpy="0 0 0"/>
            <mass value="0.2" />
            <inertia ixx="0.000411666666667" ixy="0.0" ixz="0.0" iyy="0.000411666666667" iyz="0.0" izz="0.0049"/>
        </inertial>
        <collision>
            <origin xyz="0 0 0.05" rpy="0 0 0"/>
            <geometry>
                <cylinder radius="0.07" length="0.1"/>
            </geometry>
        </collision>
                <visual>
            <origin rpy="0.0 0 0" xyz="0 0 0"/>
            <geometry>
                <mesh filename="package://jibo_description/models/jibo/meshes/jibo_final_parts_body_v3.dae"/>
            </geometry>
        </visual>
    </link>

    <gazebo reference="body_link">
        <kp>100.0</kp>
        <kd>100.0</kd>
        <mu1>10.0</mu1>
        <mu2>10.0</mu2>
        <material>Gazebo/White</material>
    </gazebo>

    <joint name="waist_body_joint" type="revolute">
        <parent link="waist_link"/>
        <child link="body_link"/>
        <origin xyz="0 0.0055 0.055" rpy="-0.15 0 0"/>
        <limit lower="-0.6" upper="0.6" effort="1" velocity="1"/>
        <axis xyz="0 0 1"/>
        </joint>

    <transmission name="tran2">
        <type>transmission_interface/SimpleTransmission</type>
        <joint name="waist_body_joint">
            <hardwareInterface>EffortJointInterface</hardwareInterface>
        </joint>
        <actuator name="motor2">
            <hardwareInterface>EffortJointInterface</hardwareInterface>
            <mechanicalReduction>1</mechanicalReduction>
        </actuator>
    </transmission>

    <link name="head_link">
            <inertial>
            <origin xyz="0 0 0" rpy="0 0 0"/>
            <mass value="0.1" />
            <inertia ixx="0.0004" ixy="0.0" ixz="0.0" iyy="0.0004" iyz="0.0" izz="0.0004"/>
        </inertial>
        <collision>
            <origin xyz="0 0 0" rpy="0 0 0"/>
            <geometry>
                <sphere radius="0.1"/>
            </geometry>
        </collision>
                <visual>
            <origin rpy="0.0 0 0" xyz="0 0 0"/>
            <geometry>
                <mesh filename="package://jibo_description/models/jibo/meshes/jibo_final_parts_head_v5.dae"/>
            </geometry>
        </visual>
    </link>

    <gazebo reference="head_link">
        <kp>100.0</kp>
        <kd>100.0</kd>
        <mu1>10.0</mu1>
        <mu2>10.0</mu2>
        <material>Gazebo/Black</material>
    </gazebo>

    <joint name="body_head_joint" type="continuous">
        <parent link="body_link"/>
        <child link="head_link"/>
        <origin xyz="0 0.0 0.15" rpy="-0.3 0 0"/>
        <limit effort="1.0" velocity="1.0"/>
        <axis xyz="0 0 1"/>
    </joint>

    <transmission name="tran3">
        <type>transmission_interface/SimpleTransmission</type>
        <joint name="body_head_joint">
            <hardwareInterface>EffortJointInterface</hardwareInterface>
        </joint>
        <actuator name="motor3">
            <hardwareInterface>EffortJointInterface</hardwareInterface>
            <mechanicalReduction>1</mechanicalReduction>
        </actuator>
    </transmission>

    <link name="camera_link">
        <inertial>
            <origin xyz="0 0 0" rpy="0 0 0"/>
            <mass value="0.001" />
            <inertia ixx="9.1875e-09" ixy="0.0" ixz="0.0" iyy="9.1875e-09" iyz="0.0" izz="1.378125e-08"/>
        </inertial>
		<visual>
            <origin rpy="0.0 0 0" xyz="0 0 0"/>
            <geometry>
                <box size="0.005 0.005 0.005"/>
            </geometry>
            <material name="blue"/>
        </visual>

	</link>

    <gazebo reference="camera_link">
        <material>Gazebo/Blue</material>
    </gazebo>

     <joint name="camera_joint" type="fixed">
        <parent link="head_link"/>
        <child link="camera_link"/>
        <origin xyz="0 0.0002 0.1" rpy="0 0 0"/>
    </joint>

    <gazebo reference="camera_link">
    <sensor type="camera" name="camera1">
      <update_rate>15.0</update_rate>
      <camera name="head">

          <pose>0 0 0 0 0 1.57</pose>

        <horizontal_fov>1.3962634</horizontal_fov>
        <image>
          <width>400</width>
          <height>400</height>
          <format>R8G8B8</format>
        </image>
        <clip>
          <near>0.01</near>
          <far>100</far>
        </clip>
        <noise>
          <type>gaussian</type>
          <stddev>0.007</stddev>
        </noise>
      </camera>
      <plugin name="camera_controller" filename="libgazebo_ros_camera.so">
        <alwaysOn>true</alwaysOn>
        <updateRate>0.0</updateRate>
        <cameraName>jibo/camera1</cameraName>
        <imageTopicName>image_raw</imageTopicName>
        <cameraInfoTopicName>camera_info</cameraInfoTopicName>
        <frameName>camera_link</frameName>
        <hackBaseline>0.07</hackBaseline>
        <distortionK1>0.0</distortionK1>
        <distortionK2>0.0</distortionK2>
        <distortionK3>0.0</distortionK3>
        <distortionT1>0.0</distortionT1>
        <distortionT2>0.0</distortionT2>
      </plugin>
    </sensor>
  </gazebo>
    
</robot>